/var/spool/slurmd/job3880439/slurm_script: line 17: cd: /users/aarjun1/users/aarjun1/data/aarjun1/pathtracker/mot/InT-Models-main_temp/: No such file or directory
module: loading 'anaconda/3-5.2.0'
module: anaconda: "See https://docs.ccv.brown.edu/oscar/software/anaconda for potential issues on VNC and batch jobs"
module: unloading 'python/2.7.12'
module: warning: unknown version 'python/3.8.8'
  Please contact CCV support (support@ccv.brown.edu) if you think that software
  with this module name should be installed.
2022-01-30 17:05:25.442958: W tensorflow/stream_executor/platform/default/dso_loader.cc:64] Could not load dynamic library 'libcudart.so.11.0'; dlerror: libcudart.so.11.0: cannot open shared object file: No such file or directory; LD_LIBRARY_PATH: /gpfs/runtime/opt/intel/2017.0/lib/intel64:/gpfs/runtime/opt/intel/2017.0/mkl/lib/intel64:/gpfs/runtime/opt/java/8u111/jre/lib/amd64
2022-01-30 17:05:25.442999: I tensorflow/stream_executor/cuda/cudart_stub.cc:29] Ignore above cudart dlerror if you do not have a GPU set up on your machine.
2022-01-30 17:05:27.482359: W tensorflow/stream_executor/platform/default/dso_loader.cc:64] Could not load dynamic library 'libcudart.so.11.0'; dlerror: libcudart.so.11.0: cannot open shared object file: No such file or directory; LD_LIBRARY_PATH: /gpfs/home/aarjun1/.conda/envs/pytracker/lib/python3.8/site-packages/cv2/../../lib64:/gpfs/runtime/opt/intel/2017.0/lib/intel64:/gpfs/runtime/opt/intel/2017.0/mkl/lib/intel64:/gpfs/runtime/opt/java/8u111/jre/lib/amd64
2022-01-30 17:05:27.482488: W tensorflow/stream_executor/platform/default/dso_loader.cc:64] Could not load dynamic library 'libcublas.so.11'; dlerror: libcublas.so.11: cannot open shared object file: No such file or directory; LD_LIBRARY_PATH: /gpfs/home/aarjun1/.conda/envs/pytracker/lib/python3.8/site-packages/cv2/../../lib64:/gpfs/runtime/opt/intel/2017.0/lib/intel64:/gpfs/runtime/opt/intel/2017.0/mkl/lib/intel64:/gpfs/runtime/opt/java/8u111/jre/lib/amd64
2022-01-30 17:05:27.482576: W tensorflow/stream_executor/platform/default/dso_loader.cc:64] Could not load dynamic library 'libcublasLt.so.11'; dlerror: libcublasLt.so.11: cannot open shared object file: No such file or directory; LD_LIBRARY_PATH: /gpfs/home/aarjun1/.conda/envs/pytracker/lib/python3.8/site-packages/cv2/../../lib64:/gpfs/runtime/opt/intel/2017.0/lib/intel64:/gpfs/runtime/opt/intel/2017.0/mkl/lib/intel64:/gpfs/runtime/opt/java/8u111/jre/lib/amd64
2022-01-30 17:05:27.482667: W tensorflow/stream_executor/platform/default/dso_loader.cc:64] Could not load dynamic library 'libcufft.so.10'; dlerror: libcufft.so.10: cannot open shared object file: No such file or directory; LD_LIBRARY_PATH: /gpfs/home/aarjun1/.conda/envs/pytracker/lib/python3.8/site-packages/cv2/../../lib64:/gpfs/runtime/opt/intel/2017.0/lib/intel64:/gpfs/runtime/opt/intel/2017.0/mkl/lib/intel64:/gpfs/runtime/opt/java/8u111/jre/lib/amd64
2022-01-30 17:05:27.482754: W tensorflow/stream_executor/platform/default/dso_loader.cc:64] Could not load dynamic library 'libcurand.so.10'; dlerror: libcurand.so.10: cannot open shared object file: No such file or directory; LD_LIBRARY_PATH: /gpfs/home/aarjun1/.conda/envs/pytracker/lib/python3.8/site-packages/cv2/../../lib64:/gpfs/runtime/opt/intel/2017.0/lib/intel64:/gpfs/runtime/opt/intel/2017.0/mkl/lib/intel64:/gpfs/runtime/opt/java/8u111/jre/lib/amd64
2022-01-30 17:05:27.482840: W tensorflow/stream_executor/platform/default/dso_loader.cc:64] Could not load dynamic library 'libcusolver.so.11'; dlerror: libcusolver.so.11: cannot open shared object file: No such file or directory; LD_LIBRARY_PATH: /gpfs/home/aarjun1/.conda/envs/pytracker/lib/python3.8/site-packages/cv2/../../lib64:/gpfs/runtime/opt/intel/2017.0/lib/intel64:/gpfs/runtime/opt/intel/2017.0/mkl/lib/intel64:/gpfs/runtime/opt/java/8u111/jre/lib/amd64
2022-01-30 17:05:27.482926: W tensorflow/stream_executor/platform/default/dso_loader.cc:64] Could not load dynamic library 'libcusparse.so.11'; dlerror: libcusparse.so.11: cannot open shared object file: No such file or directory; LD_LIBRARY_PATH: /gpfs/home/aarjun1/.conda/envs/pytracker/lib/python3.8/site-packages/cv2/../../lib64:/gpfs/runtime/opt/intel/2017.0/lib/intel64:/gpfs/runtime/opt/intel/2017.0/mkl/lib/intel64:/gpfs/runtime/opt/java/8u111/jre/lib/amd64
2022-01-30 17:05:27.484041: W tensorflow/stream_executor/platform/default/dso_loader.cc:64] Could not load dynamic library 'libcudnn.so.8'; dlerror: libcudnn.so.8: cannot open shared object file: No such file or directory; LD_LIBRARY_PATH: /gpfs/home/aarjun1/.conda/envs/pytracker/lib/python3.8/site-packages/cv2/../../lib64:/gpfs/runtime/opt/intel/2017.0/lib/intel64:/gpfs/runtime/opt/intel/2017.0/mkl/lib/intel64:/gpfs/runtime/opt/java/8u111/jre/lib/amd64
2022-01-30 17:05:27.484064: W tensorflow/core/common_runtime/gpu/gpu_device.cc:1850] Cannot dlopen some GPU libraries. Please make sure the missing libraries mentioned above are installed properly if you would like to use GPU. Follow the guide at https://www.tensorflow.org/install/gpu for how to download and setup the required libraries for your platform.
Skipping registering GPU devices...
2022-01-30 17:05:27.484437: I tensorflow/core/platform/cpu_feature_guard.cc:151] This TensorFlow binary is optimized with oneAPI Deep Neural Network Library (oneDNN) to use the following CPU instructions in performance-critical operations:  AVX2 AVX512F FMA
To enable them in other operations, rebuild TensorFlow with the appropriate compiler flags.
Traceback (most recent call last):
  File "mainclean.py", line 246, in <module>
    prec1, preci, rec, f1s = multi_acc(target[:], output.data[:])
  File "/gpfs/data/tserre/aarjun1/pathtracker/mot/InT-Models-main_temp/utils/misc_functions.py", line 64, in multi_acc
    precision_val = precision(y_pred_tags, y_test)
  File "/users/aarjun1/.conda/envs/pytracker/lib/python3.8/site-packages/torch/nn/modules/module.py", line 532, in __call__
    result = self.forward(*input, **kwargs)
  File "/users/aarjun1/.conda/envs/pytracker/lib/python3.8/site-packages/torchmetrics/metric.py", line 197, in forward
    self.update(*args, **kwargs)
  File "/users/aarjun1/.conda/envs/pytracker/lib/python3.8/site-packages/torchmetrics/metric.py", line 255, in wrapped_func
    return update(*args, **kwargs)
  File "/users/aarjun1/.conda/envs/pytracker/lib/python3.8/site-packages/torchmetrics/classification/stat_scores.py", line 203, in update
    tp, fp, tn, fn = _stat_scores_update(
  File "/users/aarjun1/.conda/envs/pytracker/lib/python3.8/site-packages/torchmetrics/functional/classification/stat_scores.py", line 112, in _stat_scores_update
    preds, target, _ = _input_format_classification(
  File "/users/aarjun1/.conda/envs/pytracker/lib/python3.8/site-packages/torchmetrics/utilities/checks.py", line 392, in _input_format_classification
    case = _check_classification_inputs(
  File "/users/aarjun1/.conda/envs/pytracker/lib/python3.8/site-packages/torchmetrics/utilities/checks.py", line 273, in _check_classification_inputs
    _check_num_classes_mc(preds, target, num_classes, multiclass, implied_classes)
  File "/users/aarjun1/.conda/envs/pytracker/lib/python3.8/site-packages/torchmetrics/utilities/checks.py", line 153, in _check_num_classes_mc
    raise ValueError("The highest label in `target` should be smaller than `num_classes`.")
ValueError: The highest label in `target` should be smaller than `num_classes`.
