/var/spool/slurmd/job3737181/slurm_script: line 17: cd: /users/aarjun1/users/aarjun1/data/aarjun1/pathtracker/mot/InT-Models-main/: No such file or directory
module: loading 'anaconda/3-5.2.0'
module: anaconda: "See https://docs.ccv.brown.edu/oscar/software/anaconda for potential issues on VNC and batch jobs"
module: unloading 'python/2.7.12'
module: warning: unknown version 'python/3.8.8'
  Please contact CCV support (support@ccv.brown.edu) if you think that software
  with this module name should be installed.
2022-01-01 19:09:47.116885: W tensorflow/stream_executor/platform/default/dso_loader.cc:64] Could not load dynamic library 'libcudart.so.11.0'; dlerror: libcudart.so.11.0: cannot open shared object file: No such file or directory; LD_LIBRARY_PATH: /gpfs/runtime/opt/intel/2017.0/lib/intel64:/gpfs/runtime/opt/intel/2017.0/mkl/lib/intel64:/gpfs/runtime/opt/java/8u111/jre/lib/amd64
2022-01-01 19:09:47.116922: I tensorflow/stream_executor/cuda/cudart_stub.cc:29] Ignore above cudart dlerror if you do not have a GPU set up on your machine.
2022-01-01 19:09:49.740091: W tensorflow/stream_executor/platform/default/dso_loader.cc:64] Could not load dynamic library 'libcudart.so.11.0'; dlerror: libcudart.so.11.0: cannot open shared object file: No such file or directory; LD_LIBRARY_PATH: /gpfs/home/aarjun1/.conda/envs/pytracker/lib/python3.8/site-packages/cv2/../../lib64:/gpfs/runtime/opt/intel/2017.0/lib/intel64:/gpfs/runtime/opt/intel/2017.0/mkl/lib/intel64:/gpfs/runtime/opt/java/8u111/jre/lib/amd64
2022-01-01 19:09:49.740216: W tensorflow/stream_executor/platform/default/dso_loader.cc:64] Could not load dynamic library 'libcublas.so.11'; dlerror: libcublas.so.11: cannot open shared object file: No such file or directory; LD_LIBRARY_PATH: /gpfs/home/aarjun1/.conda/envs/pytracker/lib/python3.8/site-packages/cv2/../../lib64:/gpfs/runtime/opt/intel/2017.0/lib/intel64:/gpfs/runtime/opt/intel/2017.0/mkl/lib/intel64:/gpfs/runtime/opt/java/8u111/jre/lib/amd64
2022-01-01 19:09:49.740305: W tensorflow/stream_executor/platform/default/dso_loader.cc:64] Could not load dynamic library 'libcublasLt.so.11'; dlerror: libcublasLt.so.11: cannot open shared object file: No such file or directory; LD_LIBRARY_PATH: /gpfs/home/aarjun1/.conda/envs/pytracker/lib/python3.8/site-packages/cv2/../../lib64:/gpfs/runtime/opt/intel/2017.0/lib/intel64:/gpfs/runtime/opt/intel/2017.0/mkl/lib/intel64:/gpfs/runtime/opt/java/8u111/jre/lib/amd64
2022-01-01 19:09:49.740396: W tensorflow/stream_executor/platform/default/dso_loader.cc:64] Could not load dynamic library 'libcufft.so.10'; dlerror: libcufft.so.10: cannot open shared object file: No such file or directory; LD_LIBRARY_PATH: /gpfs/home/aarjun1/.conda/envs/pytracker/lib/python3.8/site-packages/cv2/../../lib64:/gpfs/runtime/opt/intel/2017.0/lib/intel64:/gpfs/runtime/opt/intel/2017.0/mkl/lib/intel64:/gpfs/runtime/opt/java/8u111/jre/lib/amd64
2022-01-01 19:09:49.740483: W tensorflow/stream_executor/platform/default/dso_loader.cc:64] Could not load dynamic library 'libcurand.so.10'; dlerror: libcurand.so.10: cannot open shared object file: No such file or directory; LD_LIBRARY_PATH: /gpfs/home/aarjun1/.conda/envs/pytracker/lib/python3.8/site-packages/cv2/../../lib64:/gpfs/runtime/opt/intel/2017.0/lib/intel64:/gpfs/runtime/opt/intel/2017.0/mkl/lib/intel64:/gpfs/runtime/opt/java/8u111/jre/lib/amd64
2022-01-01 19:09:49.740571: W tensorflow/stream_executor/platform/default/dso_loader.cc:64] Could not load dynamic library 'libcusolver.so.11'; dlerror: libcusolver.so.11: cannot open shared object file: No such file or directory; LD_LIBRARY_PATH: /gpfs/home/aarjun1/.conda/envs/pytracker/lib/python3.8/site-packages/cv2/../../lib64:/gpfs/runtime/opt/intel/2017.0/lib/intel64:/gpfs/runtime/opt/intel/2017.0/mkl/lib/intel64:/gpfs/runtime/opt/java/8u111/jre/lib/amd64
2022-01-01 19:09:49.740655: W tensorflow/stream_executor/platform/default/dso_loader.cc:64] Could not load dynamic library 'libcusparse.so.11'; dlerror: libcusparse.so.11: cannot open shared object file: No such file or directory; LD_LIBRARY_PATH: /gpfs/home/aarjun1/.conda/envs/pytracker/lib/python3.8/site-packages/cv2/../../lib64:/gpfs/runtime/opt/intel/2017.0/lib/intel64:/gpfs/runtime/opt/intel/2017.0/mkl/lib/intel64:/gpfs/runtime/opt/java/8u111/jre/lib/amd64
2022-01-01 19:09:49.742751: W tensorflow/stream_executor/platform/default/dso_loader.cc:64] Could not load dynamic library 'libcudnn.so.8'; dlerror: libcudnn.so.8: cannot open shared object file: No such file or directory; LD_LIBRARY_PATH: /gpfs/home/aarjun1/.conda/envs/pytracker/lib/python3.8/site-packages/cv2/../../lib64:/gpfs/runtime/opt/intel/2017.0/lib/intel64:/gpfs/runtime/opt/intel/2017.0/mkl/lib/intel64:/gpfs/runtime/opt/java/8u111/jre/lib/amd64
2022-01-01 19:09:49.742775: W tensorflow/core/common_runtime/gpu/gpu_device.cc:1850] Cannot dlopen some GPU libraries. Please make sure the missing libraries mentioned above are installed properly if you would like to use GPU. Follow the guide at https://www.tensorflow.org/install/gpu for how to download and setup the required libraries for your platform.
Skipping registering GPU devices...
2022-01-01 19:09:49.743140: I tensorflow/core/platform/cpu_feature_guard.cc:151] This TensorFlow binary is optimized with oneAPI Deep Neural Network Library (oneDNN) to use the following CPU instructions in performance-critical operations:  AVX2 AVX512F FMA
To enable them in other operations, rebuild TensorFlow with the appropriate compiler flags.
Traceback (most recent call last):
  File "mainclean.py", line 200, in <module>
    output, jv_penalty = engine.model_step(model, imgs, model_name=args.model)
  File "/gpfs/data/tserre/aarjun1/pathtracker/mot/InT-Models-main/utils/engine.py", line 133, in model_step
    output, jv_penalty = model.forward(imgs)
  File "/users/aarjun1/.conda/envs/pytracker/lib/python3.8/site-packages/torch/nn/parallel/data_parallel.py", line 152, in forward
    outputs = self.parallel_apply(replicas, inputs, kwargs)
  File "/users/aarjun1/.conda/envs/pytracker/lib/python3.8/site-packages/torch/nn/parallel/data_parallel.py", line 162, in parallel_apply
    return parallel_apply(replicas, inputs, kwargs, self.device_ids[:len(replicas)])
  File "/users/aarjun1/.conda/envs/pytracker/lib/python3.8/site-packages/torch/nn/parallel/parallel_apply.py", line 85, in parallel_apply
    output.reraise()
  File "/users/aarjun1/.conda/envs/pytracker/lib/python3.8/site-packages/torch/_utils.py", line 394, in reraise
    raise self.exc_type(msg)
RuntimeError: Caught RuntimeError in replica 0 on device 0.
Original Traceback (most recent call last):
  File "/users/aarjun1/.conda/envs/pytracker/lib/python3.8/site-packages/torch/nn/parallel/parallel_apply.py", line 60, in _worker
    output = module(*input, **kwargs)
  File "/users/aarjun1/.conda/envs/pytracker/lib/python3.8/site-packages/torch/nn/modules/module.py", line 532, in __call__
    result = self.forward(*input, **kwargs)
  File "/gpfs/data/tserre/aarjun1/pathtracker/mot/InT-Models-main/models/ffhgru.py", line 550, in forward
    output = torch.cat([self.readout_conv(excitation), x[:, :, 0][:, None]], 1)
RuntimeError: invalid argument 0: Tensors must have same number of dimensions: got 5 and 4 at /opt/conda/conda-bld/pytorch_1579061855666/work/aten/src/THC/generic/THCTensorMath.cu:62

