/var/spool/slurmd/job3889866/slurm_script: line 17: cd: /users/aarjun1/users/aarjun1/data/aarjun1/pathtracker/mot/InT-Models-main_temp/: No such file or directory
module: loading 'anaconda/3-5.2.0'
module: anaconda: "See https://docs.ccv.brown.edu/oscar/software/anaconda for potential issues on VNC and batch jobs"
module: unloading 'python/2.7.12'
module: warning: unknown version 'python/3.8.8'
  Please contact CCV support (support@ccv.brown.edu) if you think that software
  with this module name should be installed.
2022-02-01 02:14:09.179052: W tensorflow/stream_executor/platform/default/dso_loader.cc:64] Could not load dynamic library 'libcudart.so.11.0'; dlerror: libcudart.so.11.0: cannot open shared object file: No such file or directory; LD_LIBRARY_PATH: /gpfs/runtime/opt/intel/2017.0/lib/intel64:/gpfs/runtime/opt/intel/2017.0/mkl/lib/intel64:/gpfs/runtime/opt/java/8u111/jre/lib/amd64
2022-02-01 02:14:09.179098: I tensorflow/stream_executor/cuda/cudart_stub.cc:29] Ignore above cudart dlerror if you do not have a GPU set up on your machine.
2022-02-01 02:15:12.429026: W tensorflow/stream_executor/platform/default/dso_loader.cc:64] Could not load dynamic library 'libcudart.so.11.0'; dlerror: libcudart.so.11.0: cannot open shared object file: No such file or directory; LD_LIBRARY_PATH: /gpfs/home/aarjun1/.conda/envs/pytracker/lib/python3.8/site-packages/cv2/../../lib64:/gpfs/runtime/opt/intel/2017.0/lib/intel64:/gpfs/runtime/opt/intel/2017.0/mkl/lib/intel64:/gpfs/runtime/opt/java/8u111/jre/lib/amd64
2022-02-01 02:15:12.430044: W tensorflow/stream_executor/platform/default/dso_loader.cc:64] Could not load dynamic library 'libcublas.so.11'; dlerror: libcublas.so.11: cannot open shared object file: No such file or directory; LD_LIBRARY_PATH: /gpfs/home/aarjun1/.conda/envs/pytracker/lib/python3.8/site-packages/cv2/../../lib64:/gpfs/runtime/opt/intel/2017.0/lib/intel64:/gpfs/runtime/opt/intel/2017.0/mkl/lib/intel64:/gpfs/runtime/opt/java/8u111/jre/lib/amd64
2022-02-01 02:15:12.430203: W tensorflow/stream_executor/platform/default/dso_loader.cc:64] Could not load dynamic library 'libcublasLt.so.11'; dlerror: libcublasLt.so.11: cannot open shared object file: No such file or directory; LD_LIBRARY_PATH: /gpfs/home/aarjun1/.conda/envs/pytracker/lib/python3.8/site-packages/cv2/../../lib64:/gpfs/runtime/opt/intel/2017.0/lib/intel64:/gpfs/runtime/opt/intel/2017.0/mkl/lib/intel64:/gpfs/runtime/opt/java/8u111/jre/lib/amd64
2022-02-01 02:15:12.430359: W tensorflow/stream_executor/platform/default/dso_loader.cc:64] Could not load dynamic library 'libcufft.so.10'; dlerror: libcufft.so.10: cannot open shared object file: No such file or directory; LD_LIBRARY_PATH: /gpfs/home/aarjun1/.conda/envs/pytracker/lib/python3.8/site-packages/cv2/../../lib64:/gpfs/runtime/opt/intel/2017.0/lib/intel64:/gpfs/runtime/opt/intel/2017.0/mkl/lib/intel64:/gpfs/runtime/opt/java/8u111/jre/lib/amd64
2022-02-01 02:15:12.430503: W tensorflow/stream_executor/platform/default/dso_loader.cc:64] Could not load dynamic library 'libcurand.so.10'; dlerror: libcurand.so.10: cannot open shared object file: No such file or directory; LD_LIBRARY_PATH: /gpfs/home/aarjun1/.conda/envs/pytracker/lib/python3.8/site-packages/cv2/../../lib64:/gpfs/runtime/opt/intel/2017.0/lib/intel64:/gpfs/runtime/opt/intel/2017.0/mkl/lib/intel64:/gpfs/runtime/opt/java/8u111/jre/lib/amd64
2022-02-01 02:15:12.430649: W tensorflow/stream_executor/platform/default/dso_loader.cc:64] Could not load dynamic library 'libcusolver.so.11'; dlerror: libcusolver.so.11: cannot open shared object file: No such file or directory; LD_LIBRARY_PATH: /gpfs/home/aarjun1/.conda/envs/pytracker/lib/python3.8/site-packages/cv2/../../lib64:/gpfs/runtime/opt/intel/2017.0/lib/intel64:/gpfs/runtime/opt/intel/2017.0/mkl/lib/intel64:/gpfs/runtime/opt/java/8u111/jre/lib/amd64
2022-02-01 02:15:12.430790: W tensorflow/stream_executor/platform/default/dso_loader.cc:64] Could not load dynamic library 'libcusparse.so.11'; dlerror: libcusparse.so.11: cannot open shared object file: No such file or directory; LD_LIBRARY_PATH: /gpfs/home/aarjun1/.conda/envs/pytracker/lib/python3.8/site-packages/cv2/../../lib64:/gpfs/runtime/opt/intel/2017.0/lib/intel64:/gpfs/runtime/opt/intel/2017.0/mkl/lib/intel64:/gpfs/runtime/opt/java/8u111/jre/lib/amd64
2022-02-01 02:15:12.431720: W tensorflow/stream_executor/platform/default/dso_loader.cc:64] Could not load dynamic library 'libcudnn.so.8'; dlerror: libcudnn.so.8: cannot open shared object file: No such file or directory; LD_LIBRARY_PATH: /gpfs/home/aarjun1/.conda/envs/pytracker/lib/python3.8/site-packages/cv2/../../lib64:/gpfs/runtime/opt/intel/2017.0/lib/intel64:/gpfs/runtime/opt/intel/2017.0/mkl/lib/intel64:/gpfs/runtime/opt/java/8u111/jre/lib/amd64
2022-02-01 02:15:12.431761: W tensorflow/core/common_runtime/gpu/gpu_device.cc:1850] Cannot dlopen some GPU libraries. Please make sure the missing libraries mentioned above are installed properly if you would like to use GPU. Follow the guide at https://www.tensorflow.org/install/gpu for how to download and setup the required libraries for your platform.
Skipping registering GPU devices...
2022-02-01 02:15:12.432361: I tensorflow/core/platform/cpu_feature_guard.cc:151] This TensorFlow binary is optimized with oneAPI Deep Neural Network Library (oneDNN) to use the following CPU instructions in performance-critical operations:  AVX2 AVX512F FMA
To enable them in other operations, rebuild TensorFlow with the appropriate compiler flags.
Traceback (most recent call last):
  File "mainclean.py", line 286, in <module>
    accv, precv, recv, f1sv, losv = validate(val_loader, model, criterion, device) #, logiters=3)
  File "mainclean.py", line 65, in validate
    for i, (imgs, target) in enumerate(val_loader):
  File "/users/aarjun1/.conda/envs/pytracker/lib/python3.8/site-packages/tensorflow/python/data/ops/iterator_ops.py", line 800, in __next__
    return self._next_internal()
  File "/users/aarjun1/.conda/envs/pytracker/lib/python3.8/site-packages/tensorflow/python/data/ops/iterator_ops.py", line 783, in _next_internal
    ret = gen_dataset_ops.iterator_get_next(
  File "/users/aarjun1/.conda/envs/pytracker/lib/python3.8/site-packages/tensorflow/python/ops/gen_dataset_ops.py", line 2845, in iterator_get_next
    _ops.raise_from_not_ok_status(e, name)
  File "/users/aarjun1/.conda/envs/pytracker/lib/python3.8/site-packages/tensorflow/python/framework/ops.py", line 7107, in raise_from_not_ok_status
    raise core._status_to_exception(e) from None  # pylint: disable=protected-access
tensorflow.python.framework.errors_impl.InvalidArgumentError: Input to reshape is a tensor with 196608 values, but the requested shape has 786432
	 [[{{node Reshape}}]] [Op:IteratorGetNext]
